[2024-10-30 16:45:18,864]^;WARNING^;225^;_internal.py^;_log()^; * Debugger is active!
[2024-10-30 16:45:18,876]^;INFO^;225^;_internal.py^;_log()^; * Debugger PIN: 665-346-919
[2024-10-30 16:45:18,986]^;INFO^;225^;_internal.py^;_log()^; * Running on http://127.0.0.1:5000/ (Press CTRL+C to quit)
[2024-10-30 16:45:25,081]^;INFO^;15^;app.py^;hello_world()^;Error occured in script : [D:\DOWNLOADS\FSDS\ML11thJune\app.py] at line number : [14] error_message : [We are testing exception]
[2024-10-30 16:45:25,081]^;INFO^;16^;app.py^;hello_world()^;We are testings logging
[2024-10-30 16:45:25,082]^;INFO^;225^;_internal.py^;_log()^;127.0.0.1 - - [30/Oct/2024 16:45:25] "GET / HTTP/1.1" 200 -
